[2025-03-04T23:57:25.541+0000] {local_task_job_runner.py:123} INFO - ::group::Pre task execution logs
[2025-03-04T23:57:25.550+0000] {taskinstance.py:2612} INFO - Dependencies all met for dep_context=non-requeueable deps ti=<TaskInstance: AlphaVantage_Stock_Price_Prediction.train_model scheduled__2025-03-03T00:15:00+00:00 [queued]>
[2025-03-04T23:57:25.554+0000] {taskinstance.py:2612} INFO - Dependencies all met for dep_context=requeueable deps ti=<TaskInstance: AlphaVantage_Stock_Price_Prediction.train_model scheduled__2025-03-03T00:15:00+00:00 [queued]>
[2025-03-04T23:57:25.554+0000] {taskinstance.py:2865} INFO - Starting attempt 1 of 1
[2025-03-04T23:57:25.559+0000] {taskinstance.py:2888} INFO - Executing <Task(_PythonDecoratedOperator): train_model> on 2025-03-03 00:15:00+00:00
[2025-03-04T23:57:25.564+0000] {logging_mixin.py:190} WARNING - /home/***/.local/lib/python3.12/site-packages/***/task/task_runner/standard_task_runner.py:70 DeprecationWarning: This process (pid=333) is multi-threaded, use of fork() may lead to deadlocks in the child.
[2025-03-04T23:57:25.564+0000] {standard_task_runner.py:104} INFO - Running: ['***', 'tasks', 'run', 'AlphaVantage_Stock_Price_Prediction', 'train_model', 'scheduled__2025-03-03T00:15:00+00:00', '--job-id', '11', '--raw', '--subdir', 'DAGS_FOLDER/stockpriceprediction.py', '--cfg-path', '/tmp/tmprre2wdb4']
[2025-03-04T23:57:25.565+0000] {standard_task_runner.py:105} INFO - Job 11: Subtask train_model
[2025-03-04T23:57:25.565+0000] {standard_task_runner.py:72} INFO - Started process 336 to run task
[2025-03-04T23:57:25.591+0000] {task_command.py:467} INFO - Running <TaskInstance: AlphaVantage_Stock_Price_Prediction.train_model scheduled__2025-03-03T00:15:00+00:00 [running]> on host c8e2f43182e0
[2025-03-04T23:57:25.629+0000] {taskinstance.py:3131} INFO - Exporting env vars: AIRFLOW_CTX_DAG_OWNER='***' AIRFLOW_CTX_DAG_ID='AlphaVantage_Stock_Price_Prediction' AIRFLOW_CTX_TASK_ID='train_model' AIRFLOW_CTX_EXECUTION_DATE='2025-03-03T00:15:00+00:00' AIRFLOW_CTX_TRY_NUMBER='1' AIRFLOW_CTX_DAG_RUN_ID='scheduled__2025-03-03T00:15:00+00:00'
[2025-03-04T23:57:25.630+0000] {taskinstance.py:731} INFO - ::endgroup::
[2025-03-04T23:57:26.075+0000] {cursor.py:1156} INFO - Number of results in first chunk: 1
[2025-03-04T23:57:35.572+0000] {logging_mixin.py:190} INFO - 505001 (55000): 01bacafd-0004-af89-0000-0005b553d391: Uncaught exception of type 'STATEMENT_ERROR' on line 0 at position -1 : Uncaught exception of type 'STATEMENT_ERROR' on line 2 at position 0 : Execution error in store procedure _BASECONSTRUCT:
Specified object does not exist or not authorized for the reference with allowed privileges: SELECT.
At Statement.execute, line 48 position 43
[2025-03-04T23:57:35.575+0000] {taskinstance.py:3310} ERROR - Task failed with exception
Traceback (most recent call last):
  File "/home/airflow/.local/lib/python3.12/site-packages/airflow/models/taskinstance.py", line 767, in _execute_task
    result = _execute_callable(context=context, **execute_callable_kwargs)
             ^^^^^^^^^^^^^^^^^^^^^^^^^^^^^^^^^^^^^^^^^^^^^^^^^^^^^^^^^^^^^
  File "/home/airflow/.local/lib/python3.12/site-packages/airflow/models/taskinstance.py", line 733, in _execute_callable
    return ExecutionCallableRunner(
           ^^^^^^^^^^^^^^^^^^^^^^^^
  File "/home/airflow/.local/lib/python3.12/site-packages/airflow/utils/operator_helpers.py", line 252, in run
    return self.func(*args, **kwargs)
           ^^^^^^^^^^^^^^^^^^^^^^^^^^
  File "/home/airflow/.local/lib/python3.12/site-packages/airflow/models/baseoperator.py", line 406, in wrapper
    return func(self, *args, **kwargs)
           ^^^^^^^^^^^^^^^^^^^^^^^^^^^
  File "/home/airflow/.local/lib/python3.12/site-packages/airflow/decorators/base.py", line 266, in execute
    return_value = super().execute(context)
                   ^^^^^^^^^^^^^^^^^^^^^^^^
  File "/home/airflow/.local/lib/python3.12/site-packages/airflow/models/baseoperator.py", line 406, in wrapper
    return func(self, *args, **kwargs)
           ^^^^^^^^^^^^^^^^^^^^^^^^^^^
  File "/home/airflow/.local/lib/python3.12/site-packages/airflow/operators/python.py", line 238, in execute
    return_value = self.execute_callable()
                   ^^^^^^^^^^^^^^^^^^^^^^^
  File "/home/airflow/.local/lib/python3.12/site-packages/airflow/operators/python.py", line 256, in execute_callable
    return runner.run(*self.op_args, **self.op_kwargs)
           ^^^^^^^^^^^^^^^^^^^^^^^^^^^^^^^^^^^^^^^^^^^
  File "/home/airflow/.local/lib/python3.12/site-packages/airflow/utils/operator_helpers.py", line 252, in run
    return self.func(*args, **kwargs)
           ^^^^^^^^^^^^^^^^^^^^^^^^^^
  File "/opt/airflow/dags/stockpriceprediction.py", line 86, in train_model
    cur.execute(create_model_sql)
  File "/home/airflow/.local/lib/python3.12/site-packages/snowflake/connector/cursor.py", line 1087, in execute
    Error.errorhandler_wrapper(self.connection, self, error_class, errvalue)
  File "/home/airflow/.local/lib/python3.12/site-packages/snowflake/connector/errors.py", line 284, in errorhandler_wrapper
    handed_over = Error.hand_to_other_handler(
                  ^^^^^^^^^^^^^^^^^^^^^^^^^^^^
  File "/home/airflow/.local/lib/python3.12/site-packages/snowflake/connector/errors.py", line 339, in hand_to_other_handler
    cursor.errorhandler(connection, cursor, error_class, error_value)
  File "/home/airflow/.local/lib/python3.12/site-packages/snowflake/connector/errors.py", line 215, in default_errorhandler
    raise error_class(
snowflake.connector.errors.ProgrammingError: 505001 (55000): 01bacafd-0004-af89-0000-0005b553d391: Uncaught exception of type 'STATEMENT_ERROR' on line 0 at position -1 : Uncaught exception of type 'STATEMENT_ERROR' on line 2 at position 0 : Execution error in store procedure _BASECONSTRUCT:
Specified object does not exist or not authorized for the reference with allowed privileges: SELECT.
At Statement.execute, line 48 position 43
[2025-03-04T23:57:35.595+0000] {taskinstance.py:1225} INFO - Marking task as FAILED. dag_id=AlphaVantage_Stock_Price_Prediction, task_id=train_model, run_id=scheduled__2025-03-03T00:15:00+00:00, execution_date=20250303T001500, start_date=20250304T235725, end_date=20250304T235735
[2025-03-04T23:57:35.608+0000] {taskinstance.py:340} INFO - ::group::Post task execution logs
[2025-03-04T23:57:35.609+0000] {standard_task_runner.py:124} ERROR - Failed to execute job 11 for task train_model (505001 (55000): 01bacafd-0004-af89-0000-0005b553d391: Uncaught exception of type 'STATEMENT_ERROR' on line 0 at position -1 : Uncaught exception of type 'STATEMENT_ERROR' on line 2 at position 0 : Execution error in store procedure _BASECONSTRUCT:
Specified object does not exist or not authorized for the reference with allowed privileges: SELECT.
At Statement.execute, line 48 position 43; 336)
Traceback (most recent call last):
  File "/home/airflow/.local/lib/python3.12/site-packages/airflow/task/task_runner/standard_task_runner.py", line 117, in _start_by_fork
    ret = args.func(args, dag=self.dag)
          ^^^^^^^^^^^^^^^^^^^^^^^^^^^^^
  File "/home/airflow/.local/lib/python3.12/site-packages/airflow/cli/cli_config.py", line 49, in command
    return func(*args, **kwargs)
           ^^^^^^^^^^^^^^^^^^^^^
  File "/home/airflow/.local/lib/python3.12/site-packages/airflow/utils/cli.py", line 115, in wrapper
    return f(*args, **kwargs)
           ^^^^^^^^^^^^^^^^^^
  File "/home/airflow/.local/lib/python3.12/site-packages/airflow/cli/commands/task_command.py", line 483, in task_run
    task_return_code = _run_task_by_selected_method(args, _dag, ti)
                       ^^^^^^^^^^^^^^^^^^^^^^^^^^^^^^^^^^^^^^^^^^^^
  File "/home/airflow/.local/lib/python3.12/site-packages/airflow/cli/commands/task_command.py", line 256, in _run_task_by_selected_method
    return _run_raw_task(args, ti)
           ^^^^^^^^^^^^^^^^^^^^^^^
  File "/home/airflow/.local/lib/python3.12/site-packages/airflow/cli/commands/task_command.py", line 341, in _run_raw_task
    return ti._run_raw_task(
           ^^^^^^^^^^^^^^^^^
  File "/home/airflow/.local/lib/python3.12/site-packages/airflow/utils/session.py", line 97, in wrapper
    return func(*args, session=session, **kwargs)
           ^^^^^^^^^^^^^^^^^^^^^^^^^^^^^^^^^^^^^^
  File "/home/airflow/.local/lib/python3.12/site-packages/airflow/models/taskinstance.py", line 3004, in _run_raw_task
    return _run_raw_task(
           ^^^^^^^^^^^^^^
  File "/home/airflow/.local/lib/python3.12/site-packages/airflow/models/taskinstance.py", line 273, in _run_raw_task
    TaskInstance._execute_task_with_callbacks(
  File "/home/airflow/.local/lib/python3.12/site-packages/airflow/models/taskinstance.py", line 3158, in _execute_task_with_callbacks
    result = self._execute_task(context, task_orig)
             ^^^^^^^^^^^^^^^^^^^^^^^^^^^^^^^^^^^^^^
  File "/home/airflow/.local/lib/python3.12/site-packages/airflow/models/taskinstance.py", line 3182, in _execute_task
    return _execute_task(self, context, task_orig)
           ^^^^^^^^^^^^^^^^^^^^^^^^^^^^^^^^^^^^^^^
  File "/home/airflow/.local/lib/python3.12/site-packages/airflow/models/taskinstance.py", line 767, in _execute_task
    result = _execute_callable(context=context, **execute_callable_kwargs)
             ^^^^^^^^^^^^^^^^^^^^^^^^^^^^^^^^^^^^^^^^^^^^^^^^^^^^^^^^^^^^^
  File "/home/airflow/.local/lib/python3.12/site-packages/airflow/models/taskinstance.py", line 733, in _execute_callable
    return ExecutionCallableRunner(
           ^^^^^^^^^^^^^^^^^^^^^^^^
  File "/home/airflow/.local/lib/python3.12/site-packages/airflow/utils/operator_helpers.py", line 252, in run
    return self.func(*args, **kwargs)
           ^^^^^^^^^^^^^^^^^^^^^^^^^^
  File "/home/airflow/.local/lib/python3.12/site-packages/airflow/models/baseoperator.py", line 406, in wrapper
    return func(self, *args, **kwargs)
           ^^^^^^^^^^^^^^^^^^^^^^^^^^^
  File "/home/airflow/.local/lib/python3.12/site-packages/airflow/decorators/base.py", line 266, in execute
    return_value = super().execute(context)
                   ^^^^^^^^^^^^^^^^^^^^^^^^
  File "/home/airflow/.local/lib/python3.12/site-packages/airflow/models/baseoperator.py", line 406, in wrapper
    return func(self, *args, **kwargs)
           ^^^^^^^^^^^^^^^^^^^^^^^^^^^
  File "/home/airflow/.local/lib/python3.12/site-packages/airflow/operators/python.py", line 238, in execute
    return_value = self.execute_callable()
                   ^^^^^^^^^^^^^^^^^^^^^^^
  File "/home/airflow/.local/lib/python3.12/site-packages/airflow/operators/python.py", line 256, in execute_callable
    return runner.run(*self.op_args, **self.op_kwargs)
           ^^^^^^^^^^^^^^^^^^^^^^^^^^^^^^^^^^^^^^^^^^^
  File "/home/airflow/.local/lib/python3.12/site-packages/airflow/utils/operator_helpers.py", line 252, in run
    return self.func(*args, **kwargs)
           ^^^^^^^^^^^^^^^^^^^^^^^^^^
  File "/opt/airflow/dags/stockpriceprediction.py", line 86, in train_model
    cur.execute(create_model_sql)
  File "/home/airflow/.local/lib/python3.12/site-packages/snowflake/connector/cursor.py", line 1087, in execute
    Error.errorhandler_wrapper(self.connection, self, error_class, errvalue)
  File "/home/airflow/.local/lib/python3.12/site-packages/snowflake/connector/errors.py", line 284, in errorhandler_wrapper
    handed_over = Error.hand_to_other_handler(
                  ^^^^^^^^^^^^^^^^^^^^^^^^^^^^
  File "/home/airflow/.local/lib/python3.12/site-packages/snowflake/connector/errors.py", line 339, in hand_to_other_handler
    cursor.errorhandler(connection, cursor, error_class, error_value)
  File "/home/airflow/.local/lib/python3.12/site-packages/snowflake/connector/errors.py", line 215, in default_errorhandler
    raise error_class(
snowflake.connector.errors.ProgrammingError: 505001 (55000): 01bacafd-0004-af89-0000-0005b553d391: Uncaught exception of type 'STATEMENT_ERROR' on line 0 at position -1 : Uncaught exception of type 'STATEMENT_ERROR' on line 2 at position 0 : Execution error in store procedure _BASECONSTRUCT:
Specified object does not exist or not authorized for the reference with allowed privileges: SELECT.
At Statement.execute, line 48 position 43
[2025-03-04T23:57:35.656+0000] {local_task_job_runner.py:266} INFO - Task exited with return code 1
[2025-03-04T23:57:35.679+0000] {taskinstance.py:3925} ERROR - Error scheduling downstream tasks. Skipping it as this is entirely optional optimisation. There might be various reasons for it, please take a look at the stack trace to figure out if the root cause can be diagnosed and fixed. See the issue https://github.com/apache/***/issues/39717 for details and an example problem. If you would like to get help in solving root cause, open discussion with all details with your managed service support or in Airflow repository.
Traceback (most recent call last):
  File "/home/airflow/.local/lib/python3.12/site-packages/airflow/models/taskinstance.py", line 3921, in schedule_downstream_tasks
    return TaskInstance._schedule_downstream_tasks(
           ^^^^^^^^^^^^^^^^^^^^^^^^^^^^^^^^^^^^^^^^
  File "/home/airflow/.local/lib/python3.12/site-packages/airflow/utils/session.py", line 94, in wrapper
    return func(*args, **kwargs)
           ^^^^^^^^^^^^^^^^^^^^^
  File "/home/airflow/.local/lib/python3.12/site-packages/airflow/models/taskinstance.py", line 3870, in _schedule_downstream_tasks
    partial_dag = task.dag.partial_subset(
                  ^^^^^^^^^^^^^^^^^^^^^^^^
  File "/home/airflow/.local/lib/python3.12/site-packages/airflow/models/dag.py", line 2664, in partial_subset
    t.task_id: _deepcopy_task(t)
               ^^^^^^^^^^^^^^^^^
  File "/home/airflow/.local/lib/python3.12/site-packages/airflow/models/dag.py", line 2661, in _deepcopy_task
    return copy.deepcopy(t, memo)
           ^^^^^^^^^^^^^^^^^^^^^^
  File "/usr/local/lib/python3.12/copy.py", line 143, in deepcopy
    y = copier(memo)
        ^^^^^^^^^^^^
  File "/home/airflow/.local/lib/python3.12/site-packages/airflow/models/baseoperator.py", line 1388, in __deepcopy__
    setattr(result, k, copy.deepcopy(v, memo))
                       ^^^^^^^^^^^^^^^^^^^^^^
  File "/usr/local/lib/python3.12/copy.py", line 136, in deepcopy
    y = copier(x, memo)
        ^^^^^^^^^^^^^^^
  File "/usr/local/lib/python3.12/copy.py", line 221, in _deepcopy_dict
    y[deepcopy(key, memo)] = deepcopy(value, memo)
                             ^^^^^^^^^^^^^^^^^^^^^
  File "/usr/local/lib/python3.12/copy.py", line 136, in deepcopy
    y = copier(x, memo)
        ^^^^^^^^^^^^^^^
  File "/usr/local/lib/python3.12/copy.py", line 201, in _deepcopy_tuple
    y = [deepcopy(a, memo) for a in x]
         ^^^^^^^^^^^^^^^^^
  File "/usr/local/lib/python3.12/copy.py", line 162, in deepcopy
    y = _reconstruct(x, memo, *rv)
        ^^^^^^^^^^^^^^^^^^^^^^^^^^
  File "/usr/local/lib/python3.12/copy.py", line 259, in _reconstruct
    state = deepcopy(state, memo)
            ^^^^^^^^^^^^^^^^^^^^^
  File "/usr/local/lib/python3.12/copy.py", line 136, in deepcopy
    y = copier(x, memo)
        ^^^^^^^^^^^^^^^
  File "/usr/local/lib/python3.12/copy.py", line 221, in _deepcopy_dict
    y[deepcopy(key, memo)] = deepcopy(value, memo)
                             ^^^^^^^^^^^^^^^^^^^^^
  File "/usr/local/lib/python3.12/copy.py", line 162, in deepcopy
    y = _reconstruct(x, memo, *rv)
        ^^^^^^^^^^^^^^^^^^^^^^^^^^
  File "/usr/local/lib/python3.12/copy.py", line 259, in _reconstruct
    state = deepcopy(state, memo)
            ^^^^^^^^^^^^^^^^^^^^^
  File "/usr/local/lib/python3.12/copy.py", line 136, in deepcopy
    y = copier(x, memo)
        ^^^^^^^^^^^^^^^
  File "/usr/local/lib/python3.12/copy.py", line 221, in _deepcopy_dict
    y[deepcopy(key, memo)] = deepcopy(value, memo)
                             ^^^^^^^^^^^^^^^^^^^^^
  File "/usr/local/lib/python3.12/copy.py", line 151, in deepcopy
    rv = reductor(4)
         ^^^^^^^^^^^
TypeError: cannot pickle '_thread.lock' object
[2025-03-04T23:57:35.683+0000] {local_task_job_runner.py:245} INFO - ::endgroup::
